nohup: Eingabe wird ignoriert
Entering showtime status:  2023-04-30 08:52:01
Entering ready status:  2023-05-07 17:12:26
Entering training status:  2023-05-07 17:12:37
Entering showtime status:  2023-05-07 17:15:31
Entering error status:  2023-05-10 23:11:24
Traceback (most recent call last):
  File "/usr/lib/python3/dist-packages/urllib3/connection.py", line 169, in _new_conn
    conn = connection.create_connection(
  File "/usr/lib/python3/dist-packages/urllib3/util/connection.py", line 73, in create_connection
    for res in socket.getaddrinfo(host, port, family, socket.SOCK_STREAM):
  File "/usr/lib/python3.9/socket.py", line 953, in getaddrinfo
    for res in _socket.getaddrinfo(host, port, family, type, proto, flags):
socket.gaierror: [Errno -3] Temporary failure in name resolution

During handling of the above exception, another exception occurred:

Traceback (most recent call last):
  File "/usr/lib/python3/dist-packages/urllib3/connectionpool.py", line 699, in urlopen
    httplib_response = self._make_request(
  File "/usr/lib/python3/dist-packages/urllib3/connectionpool.py", line 394, in _make_request
    conn.request(method, url, **httplib_request_kw)
  File "/usr/lib/python3/dist-packages/urllib3/connection.py", line 234, in request
    super(HTTPConnection, self).request(method, url, body=body, headers=headers)
  File "/usr/lib/python3.9/http/client.py", line 1255, in request
    self._send_request(method, url, body, headers, encode_chunked)
  File "/usr/lib/python3.9/http/client.py", line 1301, in _send_request
    self.endheaders(body, encode_chunked=encode_chunked)
  File "/usr/lib/python3.9/http/client.py", line 1250, in endheaders
    self._send_output(message_body, encode_chunked=encode_chunked)
  File "/usr/lib/python3.9/http/client.py", line 1010, in _send_output
    self.send(msg)
  File "/usr/lib/python3.9/http/client.py", line 950, in send
    self.connect()
  File "/usr/lib/python3/dist-packages/urllib3/connection.py", line 200, in connect
    conn = self._new_conn()
  File "/usr/lib/python3/dist-packages/urllib3/connection.py", line 181, in _new_conn
    raise NewConnectionError(
urllib3.exceptions.NewConnectionError: <urllib3.connection.HTTPConnection object at 0x7f956aac10>: Failed to establish a new connection: [Errno -3] Temporary failure in name resolution

During handling of the above exception, another exception occurred:

Traceback (most recent call last):
  File "/usr/lib/python3/dist-packages/requests/adapters.py", line 439, in send
    resp = conn.urlopen(
  File "/usr/lib/python3/dist-packages/urllib3/connectionpool.py", line 755, in urlopen
    retries = retries.increment(
  File "/usr/lib/python3/dist-packages/urllib3/util/retry.py", line 574, in increment
    raise MaxRetryError(_pool, url, error or ResponseError(cause))
urllib3.exceptions.MaxRetryError: HTTPConnectionPool(host='philipshuebridge', port=80): Max retries exceeded with url: /api/UQxp-qKYY3bukdq5DK9rM-N59tJ9pLUGOLZlhaMt/groups/17/action/ (Caused by NewConnectionError('<urllib3.connection.HTTPConnection object at 0x7f956aac10>: Failed to establish a new connection: [Errno -3] Temporary failure in name resolution'))

During handling of the above exception, another exception occurred:

Traceback (most recent call last):
  File "/home/pi/github/Get_Vigor165_DSL_Status/Get_Vigor165_DSL_Status.py", line 233, in <module>
    STATUS = get_adsl_status(0)
  File "/home/pi/github/Get_Vigor165_DSL_Status/Get_Vigor165_DSL_Status.py", line 183, in get_adsl_status
    set_colour("red")
  File "/home/pi/github/Get_Vigor165_DSL_Status/Get_Vigor165_DSL_Status.py", line 158, in set_colour
    requests.put("http://" + HUE_BRIDGE_IP + "/api/"  + API_KEY + "/groups/" + GROUP_NR + "/action/", headers=HEADERS, data=colour)
  File "/usr/lib/python3/dist-packages/requests/api.py", line 134, in put
    return request('put', url, data=data, **kwargs)
  File "/usr/lib/python3/dist-packages/requests/api.py", line 61, in request
    return session.request(method=method, url=url, **kwargs)
  File "/usr/lib/python3/dist-packages/requests/sessions.py", line 542, in request
    resp = self.send(prep, **send_kwargs)
  File "/usr/lib/python3/dist-packages/requests/sessions.py", line 655, in send
    r = adapter.send(request, **kwargs)
  File "/usr/lib/python3/dist-packages/requests/adapters.py", line 516, in send
    raise ConnectionError(e, request=request)
requests.exceptions.ConnectionError: HTTPConnectionPool(host='philipshuebridge', port=80): Max retries exceeded with url: /api/UQxp-qKYY3bukdq5DK9rM-N59tJ9pLUGOLZlhaMt/groups/17/action/ (Caused by NewConnectionError('<urllib3.connection.HTTPConnection object at 0x7f956aac10>: Failed to establish a new connection: [Errno -3] Temporary failure in name resolution'))
